Workbook

Sheet Pumping Data
B1: Well Sites/Aquifers
B2: Upper Floridan 051-0010 | H2: Miocene 051-0013
A3: Date | B3: Well 101 | C3: Well 102 | D3: Well 103 | F3: Well 104 | G3: UF. Total | H3: Well 101 | I3: M. Total
B4: Westwood | C4: EPOC | D4: Waterford Ct | F4: Millcreek
A5: 42005 | D5: N/A | G5: =SUM(B5:C5,F5)/1000000 -> 0 | I5: =H5/1000000 -> 0
A6: =A5+1 -> 42006 | D6: N/A | G6: =SUM(B6:C6,F6)/1000000 -> 0 | I6: =H6/1000000 -> 0
A7: =A6+1 -> 42007 | D7: N/A | G7: =SUM(B7:C7,F7)/1000000 -> 0 | I7: =H7/1000000 -> 0
A8: =A7+1 -> 42008 | D8: N/A | G8: =SUM(B8:C8,F8)/1000000 -> 0 | I8: =H8/1000000 -> 0
A9: =A8+1 -> 42009 | D9: N/A | G9: =SUM(B9:C9,F9)/1000000 -> 0 | I9: =H9/1000000 -> 0
A10: =A9+1 -> 42010 | D10: N/A | G10: =SUM(B10:C10,F10)/1000000 -> 0 | I10: =H10/1000000 -> 0
A11: =A10+1 -> 42011 | D11: N/A | G11: =SUM(B11:C11,F11)/1000000 -> 0 | I11: =H4/1000000 -> 0
A12: =A11+1 -> 42012 | D12: N/A | G12: =SUM(B12:C12,F12)/1000000 -> 0 | I12: =H5/1000000 -> 0
A13: =A12+1 -> 42013 | D13: N/A | G13: =SUM(B13:C13,F13)/1000000 -> 0 | I13: =H6/1000000 -> 0
A14: =A13+1 -> 42014 | D14: N/A | G14: =SUM(B14:C14,F14)/1000000 -> 0 | I14: =H7/1000000 -> 0
A15: =A14+1 -> 42015 | D15: N/A | G15: =SUM(B15:C15,F15)/1000000 -> 0 | I15: =H8/1000000 -> 0
A16: =A15+1 -> 42016 | D16: N/A | G16: =SUM(B16:C16,F16)/1000000 -> 0 | I16: =H9/1000000 -> 0
A17: =A16+1 -> 42017 | D17: N/A | G17: =SUM(B17:C17,F17)/1000000 -> 0 | I17: =H10/1000000 -> 0
A18: =A17+1 -> 42018 | D18: N/A | G18: =SUM(B18:C18,F18)/1000000 -> 0 | I18: =H11/1000000 -> 0
A19: =A18+1 -> 42019 | D19: N/A | G19: =SUM(B19:C19,F19)/1000000 -> 0 | I19: =H12/1000000 -> 0
A20: =A19+1 -> 42020 | D20: N/A | G20: =SUM(B20:C20,F20)/1000000 -> 0 | I20: =H13/1000000 -> 0
A21: =A20+1 -> 42021 | D21: N/A | G21: =SUM(B21:C21,F21)/1000000 -> 0 | I21: =H14/1000000 -> 0
A22: =A21+1 -> 42022 | D22: N/A | G22: =SUM(B22:C22,F22)/1000000 -> 0 | I22: =H15/1000000 -> 0
... A35: =A34+1 -> 42035 | D35: N/A | G35: =SUM(B35:C35,F35)/1000000 -> 0 | I35: =H28/1000000 -> 0

Sheet Monthly Withdrawal Report
A1: Georgia Environmental Protection Division
A2: Water Withdrawal Permitting Program - Groundwater Unit
A3: Monthly Groundwater Withdrawal Report | H3: Report Month/YR: | I3: 01/01/2000
A5: For permit holders who maintain a Groundwater Use Permit that allows withdrawal from multiple aquifers, please report usage from each aquifer | H5: GW Withdrawal Permit Number: | I5: 051-0010, 051-0013
A6: seperately. Use the additional columns in the table below to list the aquifer name and the reported usage from that individual aquifer.
A7: Day of Month | B7: Aquifer 1 | C7: Aquifer 2 | D7: Aquifer 3 | E7: Aquifer 4 | F7: Aquifer 5 | H7: County | I7: Effingham
A8: (Aquifer name) | B8: Upper Floridan 051-0010 | C8: Miocene 051-0013 | H8: Permit Holder: | I8: Coastal Water Co.
A9: 1 | B9: ='Pumping Data'!G5 -> 0 | C9: ='Pumping Data'!I5 -> 0
A10: 2 | B10: ='Pumping Data'!G6 -> 0 | C10: ='Pumping Data'!I6 -> 0 | H10: Permit Address: | I10: 119 W. Oglethorpe Ave
A11: 3 | B11: ='Pumping Data'!G7 -> 0 | C11: ='Pumping Data'!I7 -> 0 | I11: Savannah, GA. 31401
A12: 4 | B12: ='Pumping Data'!G8 -> 0 | C12: ='Pumping Data'!I8 -> 0
A13: 5 | B13: ='Pumping Data'!G9 -> 0 | C13: ='Pumping Data'!I9 -> 0 | H13: Contact Person: | I13: Kim Abbott
A14: 6 | B14: ='Pumping Data'!G10 -> 0 | C14: ='Pumping Data'!I10 -> 0 | H14: Send to: Georgia Environmental Protection Division
A15: 7 | B15: ='Pumping Data'!G11 -> 0 | C15: ='Pumping Data'!I11 -> 0 | H15: Drinking Water & Water Withdrawal Program
A16: 8 | B16: ='Pumping Data'!G12 -> 0 | C16: ='Pumping Data'!I12 -> 0 | H16: Engineering & Permitting - Groundwater Unit
A17: 9 | B17: ='Pumping Data'!G13 -> 0 | C17: ='Pumping Data'!I13 -> 0 | H17: 2 Martin Luther King Jr. Dr., S.E.
A18: 10 | B18: ='Pumping Data'!G14 -> 0 | C18: ='Pumping Data'!I14 -> 0 | H18: East Floyd Towers, Suite 1362
A19: 11 | B19: ='Pumping Data'!G15 -> 0 | C19: ='Pumping Data'!I15 -> 0 | H19: Atlanta, GA 30334-9000
A20: 12 | B20: ='Pumping Data'!G16 -> 0 | C20: ='Pumping Data'!I16 -> 0 | H20: Phone: (404) 463-1511
A21: 13 | B21: ='Pumping Data'!G17 -> 0 | C21: ='Pumping Data'!I17 -> 0 | H21: E-mail: ground.water@dnr.ga.gov
A22: 14 | B22: ='Pumping Data'!G18 -> 0 | C22: ='Pumping Data'!I18 -> 0 | H22: I certify that all information contained on this form is
A23: 15 | B23: ='Pumping Data'!G19 -> 0 | C23: ='Pumping Data'!I19 -> 0 | H23: correct and true to the best of my knowledge.
A24: 16 | B24: ='Pumping Data'!G20 -> 0 | C24: ='Pumping Data'!I20 -> 0
A25: 17 | B25: ='Pumping Data'!G21 -> 0 | C25: ='Pumping Data'!I21 -> 0 | H25: ____________Kim Abbott_____________ ____01/01/2000_
A26: 18 | B26: ='Pumping Data'!G22 -> 0 | C26: ='Pumping Data'!I22 -> 0 | H26: Signature Date
A27: 19 | B27: ='Pumping Data'!G23 -> 0 | C27: ='Pumping Data'!I23 -> 0
A28: 20 | B28: ='Pumping Data'!G24 -> 0 | C28: ='Pumping Data'!I24 -> 0
A29: 21 | B29: ='Pumping Data'!G25 -> 0 | C29: ='Pumping Data'!I25 -> 0 | H29: Print Name
A30: 22 | B30: ='Pumping Data'!G26 -> 0 | C30: ='Pumping Data'!I26 -> 0
A31: 23 | B31: ='Pumping Data'!G27 -> 0 | C31: ='Pumping Data'!I27 -> 0 | H31: Operator
A32: 24 | B32: ='Pumping Data'!G28 -> 0 | C32: ='Pumping Data'!I28 -> 0 | H32: Title
A33: 25 | B33: ='Pumping Data'!G29 -> 0 | C33: ='Pumping Data'!I29 -> 0
A34: 26 | B34: ='Pumping Data'!G30 -> 0 | C34: ='Pumping Data'!I30 -> 0 | H34: (_____912_______) _________233_____ - _____3254_____
A35: 27 | B35: ='Pumping Data'!G31 -> 0 | C35: ='Pumping Data'!I31 -> 0 | H35: Phone Number
A36: 28 | B36: ='Pumping Data'!G32 -> 0 | C36: ='Pumping Data'!I32 -> 0 | H36: _(____912_______) ________233______ - ______3254____
A37: 29 | B37: ='Pumping Data'!G33 -> 0 | C37: ='Pumping Data'!I33 -> 0 | H37: Fax Number
A38: 30 | B38: ='Pumping Data'!G34 -> 0 | C38: ='Pumping Data'!I34 -> 0
A39: 31 | B39: ='Pumping Data'!G35 -> 0 | C39: ='Pumping Data'!I35 -> 0
A40: Total (MG)* | B40: =SUM(B9:B39) -> 0 | C40: =SUM(C9:C39) -> 0 | D40: =SUM(D9:D39)/1000000 -> 0 | E40: =SUM(E9:E39)/1000000 -> 0 | F40: =SUM(F9:F39)/1000000 -> 0 | H40: Email Address
A41: Average (MGD)** | B41: =AVERAGE(B9:B39) -> 0 | C41: =AVERAGE(C9:C39) -> 0 | H41: *: MG represents millions of gallons.
...
